Rotation [(-20, 20), (-20, 20), (-20, 20)]
Traceback (most recent call last):
  File "/home/ssommers/.local/lib/python3.9/site-packages/pandas/core/indexes/base.py", line 3652, in get_loc
    return self._engine.get_loc(casted_key)
  File "pandas/_libs/index.pyx", line 147, in pandas._libs.index.IndexEngine.get_loc
  File "pandas/_libs/index.pyx", line 176, in pandas._libs.index.IndexEngine.get_loc
  File "pandas/_libs/hashtable_class_helper.pxi", line 7080, in pandas._libs.hashtable.PyObjectHashTable.get_item
  File "pandas/_libs/hashtable_class_helper.pxi", line 7088, in pandas._libs.hashtable.PyObjectHashTable.get_item
KeyError: 0

The above exception was the direct cause of the following exception:

Traceback (most recent call last):
  File "/scratch-shared/ssommers/dataloaderDuplicate.py", line 628, in <module>
    test(workspace)
  File "/scratch-shared/ssommers/dataloaderDuplicate.py", line 599, in test
    train_loader = get_data_loader(
  File "/scratch-shared/ssommers/dataloaderDuplicate.py", line 386, in get_data_loader
    print('First dingetje', dataset[0])
  File "/home/ssommers/.local/lib/python3.9/site-packages/pandas/core/frame.py", line 3761, in __getitem__
    indexer = self.columns.get_loc(key)
  File "/home/ssommers/.local/lib/python3.9/site-packages/pandas/core/indexes/base.py", line 3654, in get_loc
    raise KeyError(key) from err
KeyError: 0

JOB STATISTICS
==============
Job ID: 2786081
Cluster: snellius
User/Group: ssommers/ssommers
State: RUNNING
Nodes: 1
Cores per node: 18
CPU Utilized: 00:00:00
CPU Efficiency: 0.00% of 00:12:00 core-walltime
Job Wall-clock time: 00:00:40
Memory Utilized: 0.00 MB (estimated maximum)
Memory Efficiency: 0.00% of 64.00 GB (64.00 GB/node)
WARNING: Efficiency statistics may be misleading for RUNNING jobs.
